Workbook

Sheet Інструкція
B1: Battery monitor rev-a: деталі для монтажу і закупівля із запасом
B2: Деталі, що паяються на плату battery-monitor-rev-a (59 шт на плату з 62 позицій BOM; J101, TP102, TP103 - площадки без деталі). ESP32-S3 і Ra-02 вже є у власника; основний магазин - IMRAD, решта (U101, U301, F501, L101, R305, U202) - VD MAIS; резистори 0603 ряду E24 можна брати і з книги власника. Аркуш «Поза платою» - що купити для монтажу в корпус (вольтметр, відповідні роз'єми, кріплення, запобіжник у проводі батареї). Ціни, наявність і мінімальні замовлення - як на сторінках магазинів 2026-10-25; перед замовленням перевірити.
B4: Налаштування (жовті клітинки можна змінювати)
B5: Кількість плат для збирання | C5: 5 | E5: PCB замовляються по 5 шт. Кількості «Потрібно» і запас на брак рахуються від цього числа.
B6: ПДВ для цін, вказаних «без ПДВ» | C6: 0.2 | E6: Космодром і РКС показують ціни без ПДВ; VD MAIS - з ПДВ; Prom.ua, IMRAD, Mini-Tech - як на сторінці.
B8: Категорія | C8: Запас на брак, % | D8: Мін. запас на брак, шт | E8: Навіщо
B9: Дрібні пасивні | C9: 0.2 | D9: 3 | E9: 0603/0805/1206 губляться і «відлітають» під час паяння
B10: Мікросхеми та силові | C10: 0 | D10: 1 | E10: 1 шт на випадок перегріву або неправильної орієнтації
B11: Роз'єми та кнопки | C11: 0 | D11: 1 | E11: 1 шт на випадок пошкодження
B12: Модулі | C12: 0 | D12: 0 | E12: ESP32-S3 і Ra-02 вже є у власника
B13: Без деталі | C13: 0 | D13: 0 | E13: площадки на платі, нічого не купується
B15: Підсумок (рахується автоматично)
B16: Деталі плати (із запасом): сума відомих цін, грн | C16: =Плата!S45 -> 8328.764
B17: Набори (книги): сума, грн | C17: =Набори!L6 -> 0
B18: Поза платою (вольтметр, роз'єми-відповідники, кріплення, запобіжник у проводі): сума, грн | C18: ='Поза платою'!R14 -> 808.56
B19: Разом, грн (без доставки і рядків без ціни) | C19: =C16+C17+C18 -> 9137.324
B20: Рядків без ціни (AliExpress) | C20: =Плата!S46 -> 0
B21: Рядків до покупки «в наявності» | C21: =COUNTIFS(Плата!$Q$6:$Q$44,"в наявності",Плата!$L$6:$L$44,">0") -> 33
B22: Рядків до покупки «під замовлення» (строк уточнити) | C22: =COUNTIFS(Плата!$Q$6:$Q$44,"під замовлення",Плата!$L$6:$L$44,">0") -> 2
B23: Рядків до покупки «немає» / «немає в Україні» | C23: =COUNTIFS(Плата!$Q$6:$Q$44,"немає*",Плата!$L$6:$L$44,">0") -> 0
B24: Номіналів з книги резисторів, яким її не вистачає | C24: =COUNTIF(Плата!$Q$6:$Q$44,"набору мало*") -> 0
B26: Як користуватися: 5 кроків
B27: КРОК 1. Тут, у жовтій клітинці C5, - скільки плат збираєте (зараз 5). Усі кількості перерахуються самі.
B28: КРОК 2. Аркуш «Набори»: книга резисторів 0603 вже є («Вже є» = 1); резистори 0603 зараз купуються в IMRAD, книга - безкоштовна альтернатива. «Купити» = 1, лише якщо потрібна ще одна.
B29: КРОК 3. Аркуш «Плата»: змінюйте лише жовті клітинки - «Купити щонайменше», «Вже є» (залишки після rev-c: стовпець «Деталь з rev-c»), «Джерело» і «Магазин». Зелений стовпець «ЗАМОВИТИ» - результат.
B30: КРОК 4. Аркуш «Поза платою»: вольтметр, корпуси і контакти XH, нейлонове кріплення H1-H4, тримач і запобіжник 2 А для проводу батареї. «Вже є» - якщо щось уже є.
B31: КРОК 5. Аркуш «Список покупок»: готовий перелік по магазинах. Аркуш «Кошики» - сума по кожному магазину і скільки бракує до мінімальної суми продавця Prom.ua (Filur 300, Connectors 150, DIY mag 100 грн).
B33: Корисно знати
B34: «ЗАМОВИТИ» = більше з двох: («Потрібно на всі плати» + «на брак») або «Купити щонайменше»; мінус «Вже є»; далі округлюється до мінімального замовлення і кратності магазину. «Лишиться в запасі» – що залишиться після збирання.
B35: «Купити щонайменше» зараз: дешеві мікросхеми, запобіжники, дросель, діоди, транзистори, роз'єми – 10 шт; світлодіоди, 220k 0.1 % - 20; 100 нФ 0603 і 10 кОм 1206 - 100; 22 мкФ 0805 - 50. Дорогі U101, U202, U301 - лише потреба + 1 шт на брак.
B36: «Джерело»: «магазин» - купується окремо (резистори 0603 68k, 510k, 220k, 10k, 5.1k, 22, 4.7k, 1k, 100k - упаковками по 100 шт в IMRAD; замість цього можна вибрати «книга резисторів 0603»); «є у власника» - ESP32-S3 і Ra-02 (сірі рядки); «не купується» - J101 (провід батареї), TP102/TP103.
B37: НЕ замінювати: R304/R305 (0.1 %, тонкоплівкові), R511 (2512 1 Вт, перевантаження 5 с) і F501 0.25 А (розраховані разом), F101 лише NANO2 0451002.MRL (футпринт NANO2), U101 лише SDDAR / SQDDARQ1 (не FDDAR), D102 лише однонаправлений SMAJ33A. Допустимі заміни описано в стовпці «Що купувати».
B38: Два замовлення (перевірено 2026-10-25): IMRAD - усі рядки, які він має на складі; VD MAIS - L101 SRN6045-220M, R305, U202 (власний склад, 0 тижнів) і Digi-Key через VD MAIS, 3 тижні: U101 LMR38010SQDDARQ1, F501 0466.250NRHF, 2 з 6 шт U301 - цей кошик замовляйте першим.
... B44: Джерела: KiCad BOM (02-components/battery-monitor-rev-a-bom.csv, kicad-cli 10.0.6), сторінки магазинів. Скрипти: battery-monitor-rev-a/evidence/imrad-stock-20261025/scratch/imrad-workbook/gen/ (edit_offers.py -> bom_offers.py, check_links.py, make_components_ua.py, verify_components.py, recalc_excel.ps1); дані - сторінки магазинів 2026-10-25 (скрипти component-sourcing-ukraine, вивід у imrad-workbook/live/).

Sheet Список покупок
A1: Список покупок: що і скільки замовити в кожному магазині. Рахується сам з аркушів «Плата» і «Набори»: тут нічого не змінюйте.
A2: Купуйте магазин за магазином (рядки згруповано). Порожня ціна - AliExpress: шукайте за MPN зі стовпця «Що замовити». Перед оплатою відкрийте посилання і перевірте наявність і ціну.
A3: Деталі плати
A4: Магазин | B4: Позиції на платі | C4: Що замовити | D4: Кількість | E4: Од. | F4: Ціна з ПДВ, грн/од. | G4: Сума, грн | H4: Статус | I4: Посилання | J4: Примітка | K4: ключ | L4: рядок
A5: =IF($L5="","",INDEX(Плата!$O:$O,$L5)&"") -> IMRAD | B5: =IF($L5="","",INDEX(Плата!$B:$B,$L5)&"") -> C101 | C5: =IF($L5="","",INDEX(Плата!$P:$P,$L5)&"") -> Panasonic EEEFK2A220P (точний MPN) | D5: =IF($L5="","",INDEX(Плата!$L:$L,$L5)) -> 10 | E5: =IF($L5="","",INDEX(Плата!$G:$G,$L5)&"") -> шт | F5: =IF($L5="","",INDEX(Плата!$R:$R,$L5)) -> 14.82 | G5: =IF($L5="","",INDEX(Плата!$S:$S,$L5)) -> 148.2 | H5: =IF($L5="","",INDEX(Плата!$Q:$Q,$L5)&"") -> в наявності | I5: =IF($L5="","",IF(INDEX(Плата!$AI:$AI,$L5)="","",HYPERLINK(INDEX(Плата!$AI:$AI,$L5),"відкрити"))) -> відкрити | J5: =IF($L5="","",INDEX(Плата!$U:$U,$L5)&"") -> IMRAD: «Є в наявності, на складі» (кількість не показано); ціна від 6 шт (1 шт: 16.13, від 15: 13.69, від 70: 12.38) | K5: =IFERROR(SMALL(Плата!$AJ$6:$AJ$44,1),"") -> 1006 | L5: =IF(K5="","",MOD(K5,1000)) -> 6
A6: =IF($L6="","",INDEX(Плата!$O:$O,$L6)&"") -> IMRAD | B6: =IF($L6="","",INDEX(Плата!$B:$B,$L6)&"") -> C102 | C6: =IF($L6="","",INDEX(Плата!$P:$P,$L6)&"") -> Murata GRM32EC72A106KE05L (точний MPN) | D6: =IF($L6="","",INDEX(Плата!$L:$L,$L6)) -> 10 | E6: =IF($L6="","",INDEX(Плата!$G:$G,$L6)&"") -> шт | F6: =IF($L6="","",INDEX(Плата!$R:$R,$L6)) -> 32.06 | G6: =IF($L6="","",INDEX(Плата!$S:$S,$L6)) -> 320.6 | H6: =IF($L6="","",INDEX(Плата!$Q:$Q,$L6)&"") -> в наявності | I6: =IF($L6="","",IF(INDEX(Плата!$AI:$AI,$L6)="","",HYPERLINK(INDEX(Плата!$AI:$AI,$L6),"відкрити"))) -> відкрити | J6: =IF($L6="","",INDEX(Плата!$U:$U,$L6)&"") -> IMRAD: «Є в наявності, на складі» (кількість не показано); ціна від 5 шт (1 шт: 36.53) | K6: =IFERROR(SMALL(Плата!$AJ$6:$AJ$44,2),"") -> 1007 | L6: =IF(K6="","",MOD(K6,1000)) -> 7
A7: =IF($L7="","",INDEX(Плата!$O:$O,$L7)&"") -> IMRAD | B7: =IF($L7="","",INDEX(Плата!$B:$B,$L7)&"") -> C103 | C7: =IF($L7="","",INDEX(Плата!$P:$P,$L7)&"") -> Samsung CL10B104KC8NNNC (100 нФ X7R 100 В 0603, точний MPN) | D7: =IF($L7="","",INDEX(Плата!$L:$L,$L7)) -> 100 | E7: =IF($L7="","",INDEX(Плата!$G:$G,$L7)&"") -> шт | F7: =IF($L7="","",INDEX(Плата!$R:$R,$L7)) -> 0.94 | G7: =IF($L7="","",INDEX(Плата!$S:$S,$L7)) -> 94 | H7: =IF($L7="","",INDEX(Плата!$Q:$Q,$L7)&"") -> в наявності | I7: =IF($L7="","",IF(INDEX(Плата!$AI:$AI,$L7)="","",HYPERLINK(INDEX(Плата!$AI:$AI,$L7),"відкрити"))) -> відкрити | J7: =IF($L7="","",INDEX(Плата!$U:$U,$L7)&"") -> IMRAD: «Є в наявності, на складі» (кількість не показано); ціна від 100 шт (1 шт: 1.65, від 10: 1.02) | K7: =IFERROR(SMALL(Плата!$AJ$6:$AJ$44,3),"") -> 1008 | L7: =IF(K7="","",MOD(K7,1000)) -> 8
A8: =IF($L8="","",INDEX(Плата!$O:$O,$L8)&"") -> IMRAD | B8: =IF($L8="","",INDEX(Плата!$B:$B,$L8)&"") -> C104, C202-C205, C301, C302, C402 | C8: =IF($L8="","",INDEX(Плата!$P:$P,$L8)&"") -> Samsung CL10B104KB8NNNC (100 нФ X7R 50 В 0603, точний MPN) | D8: =IF($L8="","",INDEX(Плата!$L:$L,$L8)) -> 100 | E8: =IF($L8="","",INDEX(Плата!$G:$G,$L8)&"") -> шт | F8: =IF($L8="","",INDEX(Плата!$R:$R,$L8)) -> 0.67 | G8: =IF($L8="","",INDEX(Плата!$S:$S,$L8)) -> 67 | H8: =IF($L8="","",INDEX(Плата!$Q:$Q,$L8)&"") -> в наявності | I8: =IF($L8="","",IF(INDEX(Плата!$AI:$AI,$L8)="","",HYPERLINK(INDEX(Плата!$AI:$AI,$L8),"відкрити"))) -> відкрити | J8: =IF($L8="","",INDEX(Плата!$U:$U,$L8)&"") -> IMRAD: «Є в наявності, на складі» (кількість не показано); ціна від 100 шт (1 шт: 1.65, від 10: 0.72, від 500: 0.63) | K8: =IFERROR(SMALL(Плата!$AJ$6:$AJ$44,4),"") -> 1009 | L8: =IF(K8="","",MOD(K8,1000)) -> 9
A9: =IF($L9="","",INDEX(Плата!$O:$O,$L9)&"") -> IMRAD | B9: =IF($L9="","",INDEX(Плата!$B:$B,$L9)&"") -> C105-C107, C201 | C9: =IF($L9="","",INDEX(Плата!$P:$P,$L9)&"") -> Murata GRM21BR61E226ME44L (точний MPN) | D9: =IF($L9="","",INDEX(Плата!$L:$L,$L9)) -> 50 | E9: =IF($L9="","",INDEX(Плата!$G:$G,$L9)&"") -> шт | F9: =IF($L9="","",INDEX(Плата!$R:$R,$L9)) -> 12.04 | G9: =IF($L9="","",INDEX(Плата!$S:$S,$L9)) -> 602 | H9: =IF($L9="","",INDEX(Плата!$Q:$Q,$L9)&"") -> в наявності | I9: =IF($L9="","",IF(INDEX(Плата!$AI:$AI,$L9)="","",HYPERLINK(INDEX(Плата!$AI:$AI,$L9),"відкрити"))) -> відкрити | J9: =IF($L9="","",INDEX(Плата!$U:$U,$L9)&"") -> IMRAD: «Є в наявності, на складі» (кількість не показано); ціна від 10 шт (1 шт: 13.42, від 100: 11.21). «Купити щонайменше» 50 задано, коли ціна була 2.96 грн: потреба 5 плат = 24 шт | K9: =IFERROR(SMALL(Плата!$AJ$6:$AJ$44,5),"") -> 1010 | L9: =IF(K9="","",MOD(K9,1000)) -> 10
A10: =IF($L10="","",INDEX(Плата!$O:$O,$L10)&"") -> IMRAD | B10: =IF($L10="","",INDEX(Плата!$B:$B,$L10)&"") -> C401 | C10: =IF($L10="","",INDEX(Плата!$P:$P,$L10)&"") -> Samsung CL21A106KAYNNNE (точний MPN) | D10: =IF($L10="","",INDEX(Плата!$L:$L,$L10)) -> 20 | E10: =IF($L10="","",INDEX(Плата!$G:$G,$L10)&"") -> шт | F10: =IF($L10="","",INDEX(Плата!$R:$R,$L10)) -> 3.41 | G10: =IF($L10="","",INDEX(Плата!$S:$S,$L10)) -> 68.2 | H10: =IF($L10="","",INDEX(Плата!$Q:$Q,$L10)&"") -> в наявності | I10: =IF($L10="","",IF(INDEX(Плата!$AI:$AI,$L10)="","",HYPERLINK(INDEX(Плата!$AI:$AI,$L10),"відкрити"))) -> відкрити | J10: =IF($L10="","",INDEX(Плата!$U:$U,$L10)&"") -> IMRAD: «Є в наявності, на складі» (кількість не показано); ціна від 10 шт (1 шт: 3.80, від 100: 3.18) | K10: =IFERROR(SMALL(Плата!$AJ$6:$AJ$44,6),"") -> 1011 | L10: =IF(K10="","",MOD(K10,1000)) -> 11
A11: =IF($L11="","",INDEX(Плата!$O:$O,$L11)&"") -> IMRAD | B11: =IF($L11="","",INDEX(Плата!$B:$B,$L11)&"") -> D101 | C11: =IF($L11="","",INDEX(Плата!$P:$P,$L11)&"") -> Diodes B1100-13-F (100 В, 1 А, SMA, точний MPN) | D11: =IF($L11="","",INDEX(Плата!$L:$L,$L11)) -> 10 | E11: =IF($L11="","",INDEX(Плата!$G:$G,$L11)&"") -> шт | F11: =IF($L11="","",INDEX(Плата!$R:$R,$L11)) -> 5.55 | G11: =IF($L11="","",INDEX(Плата!$S:$S,$L11)) -> 55.5 | H11: =IF($L11="","",INDEX(Плата!$Q:$Q,$L11)&"") -> в наявності | I11: =IF($L11="","",IF(INDEX(Плата!$AI:$AI,$L11)="","",HYPERLINK(INDEX(Плата!$AI:$AI,$L11),"відкрити"))) -> відкрити | J11: =IF($L11="","",INDEX(Плата!$U:$U,$L11)&"") -> IMRAD: «Є в наявності, на складі» (кількість не показано); ціна від 10 шт (1 шт: 6.07, від 50: 5.21) | K11: =IFERROR(SMALL(Плата!$AJ$6:$AJ$44,7),"") -> 1012 | L11: =IF(K11="","",MOD(K11,1000)) -> 12
A12: =IF($L12="","",INDEX(Плата!$O:$O,$L12)&"") -> IMRAD | B12: =IF($L12="","",INDEX(Плата!$B:$B,$L12)&"") -> D102 | C12: =IF($L12="","",INDEX(Плата!$P:$P,$L12)&"") -> ST SMAJ33A-TR (однонаправлений, 33 В, 400 Вт, SMA, точний MPN) | D12: =IF($L12="","",INDEX(Плата!$L:$L,$L12)) -> 10 | E12: =IF($L12="","",INDEX(Плата!$G:$G,$L12)&"") -> шт | F12: =IF($L12="","",INDEX(Плата!$R:$R,$L12)) -> 6.26 | G12: =IF($L12="","",INDEX(Плата!$S:$S,$L12)) -> 62.6 | H12: =IF($L12="","",INDEX(Плата!$Q:$Q,$L12)&"") -> в наявності | I12: =IF($L12="","",IF(INDEX(Плата!$AI:$AI,$L12)="","",HYPERLINK(INDEX(Плата!$AI:$AI,$L12),"відкрити"))) -> відкрити | J12: =IF($L12="","",INDEX(Плата!$U:$U,$L12)&"") -> IMRAD: «Є в наявності, на складі» (кількість не показано); ціна від 10 шт (1 шт: 6.85, від 50: 5.87) | K12: =IFERROR(SMALL(Плата!$AJ$6:$AJ$44,8),"") -> 1013 | L12: =IF(K12="","",MOD(K12,1000)) -> 13
A13: =IF($L13="","",INDEX(Плата!$O:$O,$L13)&"") -> IMRAD | B13: =IF($L13="","",INDEX(Плата!$B:$B,$L13)&"") -> D501 | C13: =IF($L13="","",INDEX(Плата!$P:$P,$L13)&"") -> Lite-On LTST-C191KGKT (жовто-зелений 571 нм, точний MPN) | D13: =IF($L13="","",INDEX(Плата!$L:$L,$L13)) -> 20 | E13: =IF($L13="","",INDEX(Плата!$G:$G,$L13)&"") -> шт | F13: =IF($L13="","",INDEX(Плата!$R:$R,$L13)) -> 1.74 | G13: =IF($L13="","",INDEX(Плата!$S:$S,$L13)) -> 34.8 | H13: =IF($L13="","",INDEX(Плата!$Q:$Q,$L13)&"") -> в наявності | I13: =IF($L13="","",IF(INDEX(Плата!$AI:$AI,$L13)="","",HYPERLINK(INDEX(Плата!$AI:$AI,$L13),"відкрити"))) -> відкрити | J13: =IF($L13="","",INDEX(Плата!$U:$U,$L13)&"") -> IMRAD: «Є в наявності, на складі» (кількість не показано); ціна від 10 шт (1 шт: 1.84, від 50: 1.56) | K13: =IFERROR(SMALL(Плата!$AJ$6:$AJ$44,9),"") -> 1014 | L13: =IF(K13="","",MOD(K13,1000)) -> 14
A14: =IF($L14="","",INDEX(Плата!$O:$O,$L14)&"") -> IMRAD | B14: =IF($L14="","",INDEX(Плата!$B:$B,$L14)&"") -> D502 | C14: =IF($L14="","",INDEX(Плата!$P:$P,$L14)&"") -> Kingbright KP-1608SURCK (червоний 630 нм, точний MPN) | D14: =IF($L14="","",INDEX(Плата!$L:$L,$L14)) -> 20 | E14: =IF($L14="","",INDEX(Плата!$G:$G,$L14)&"") -> шт | F14: =IF($L14="","",INDEX(Плата!$R:$R,$L14)) -> 4.69 | G14: =IF($L14="","",INDEX(Плата!$S:$S,$L14)) -> 93.8 | H14: =IF($L14="","",INDEX(Плата!$Q:$Q,$L14)&"") -> в наявності | I14: =IF($L14="","",IF(INDEX(Плата!$AI:$AI,$L14)="","",HYPERLINK(INDEX(Плата!$AI:$AI,$L14),"відкрити"))) -> відкрити | J14: =IF($L14="","",INDEX(Плата!$U:$U,$L14)&"") -> IMRAD: «Є в наявності, на складі» (кількість не показано); ціна від 10 шт (1 шт: 4.96, від 50: 4.21) | K14: =IFERROR(SMALL(Плата!$AJ$6:$AJ$44,10),"") -> 1015 | L14: =IF(K14="","",MOD(K14,1000)) -> 15
A15: =IF($L15="","",INDEX(Плата!$O:$O,$L15)&"") -> IMRAD | B15: =IF($L15="","",INDEX(Плата!$B:$B,$L15)&"") -> F101 | C15: =IF($L15="","",INDEX(Плата!$P:$P,$L15)&"") -> Littelfuse 0451002.MRL (NANO2, 2 А 125 В, точний MPN) | D15: =IF($L15="","",INDEX(Плата!$L:$L,$L15)) -> 10 | E15: =IF($L15="","",INDEX(Плата!$G:$G,$L15)&"") -> шт | F15: =IF($L15="","",INDEX(Плата!$R:$R,$L15)) -> 49.95 | G15: =IF($L15="","",INDEX(Плата!$S:$S,$L15)) -> 499.5 | H15: =IF($L15="","",INDEX(Плата!$Q:$Q,$L15)&"") -> в наявності | I15: =IF($L15="","",IF(INDEX(Плата!$AI:$AI,$L15)="","",HYPERLINK(INDEX(Плата!$AI:$AI,$L15),"відкрити"))) -> відкрити | J15: =IF($L15="","",INDEX(Плата!$U:$U,$L15)&"") -> IMRAD: «Є в наявності, на складі» (кількість не показано); ціна від 8 шт (1 шт: 57.93, від 4: 55.03, від 24: 45.86) | K15: =IFERROR(SMALL(Плата!$AJ$6:$AJ$44,11),"") -> 1016 | L15: =IF(K15="","",MOD(K15,1000)) -> 16
A16: =IF($L16="","",INDEX(Плата!$O:$O,$L16)&"") -> IMRAD | B16: =IF($L16="","",INDEX(Плата!$B:$B,$L16)&"") -> J201 | C16: =IF($L16="","",INDEX(Плата!$P:$P,$L16)&"") -> GCT USB4105-GF-A (точний MPN) | D16: =IF($L16="","",INDEX(Плата!$L:$L,$L16)) -> 10 | E16: =IF($L16="","",INDEX(Плата!$G:$G,$L16)&"") -> шт | F16: =IF($L16="","",INDEX(Плата!$R:$R,$L16)) -> 34.96 | G16: =IF($L16="","",INDEX(Плата!$S:$S,$L16)) -> 349.6 | H16: =IF($L16="","",INDEX(Плата!$Q:$Q,$L16)&"") -> в наявності | I16: =IF($L16="","",IF(INDEX(Плата!$AI:$AI,$L16)="","",HYPERLINK(INDEX(Плата!$AI:$AI,$L16),"відкрити"))) -> відкрити | J16: =IF($L16="","",INDEX(Плата!$U:$U,$L16)&"") -> IMRAD: «Є в наявності, на складі» (кількість не показано); ціна від 8 шт (1 шт: 37.65, від 4: 36.30, від 20: 33.62) | K16: =IFERROR(SMALL(Плата!$AJ$6:$AJ$44,12),"") -> 1019 | L16: =IF(K16="","",MOD(K16,1000)) -> 19
A17: =IF($L17="","",INDEX(Плата!$O:$O,$L17)&"") -> IMRAD | B17: =IF($L17="","",INDEX(Плата!$B:$B,$L17)&"") -> J503 | C17: =IF($L17="","",INDEX(Плата!$P:$P,$L17)&"") -> JST B3B-XH-A (точний MPN) | D17: =IF($L17="","",INDEX(Плата!$L:$L,$L17)) -> 10 | E17: =IF($L17="","",INDEX(Плата!$G:$G,$L17)&"") -> шт | F17: =IF($L17="","",INDEX(Плата!$R:$R,$L17)) -> 4.35 | G17: =IF($L17="","",INDEX(Плата!$S:$S,$L17)) -> 43.5 | H17: =IF($L17="","",INDEX(Плата!$Q:$Q,$L17)&"") -> в наявності | I17: =IF($L17="","",IF(INDEX(Плата!$AI:$AI,$L17)="","",HYPERLINK(INDEX(Плата!$AI:$AI,$L17),"відкрити"))) -> відкрити | J17: =IF($L17="","",INDEX(Плата!$U:$U,$L17)&"") -> IMRAD: «Є в наявності, на складі» (кількість не показано); ціна від 10 шт (1 шт: 4.82, від 35: 4.20) | K17: =IFERROR(SMALL(Плата!$AJ$6:$AJ$44,13),"") -> 1020 | L17: =IF(K17="","",MOD(K17,1000)) -> 20
A18: =IF($L18="","",INDEX(Плата!$O:$O,$L18)&"") -> IMRAD | B18: =IF($L18="","",INDEX(Плата!$B:$B,$L18)&"") -> J504 | C18: =IF($L18="","",INDEX(Плата!$P:$P,$L18)&"") -> JST B2B-XH-A (LF)(SN) (точний MPN) | D18: =IF($L18="","",INDEX(Плата!$L:$L,$L18)) -> 10 | E18: =IF($L18="","",INDEX(Плата!$G:$G,$L18)&"") -> шт | F18: =IF($L18="","",INDEX(Плата!$R:$R,$L18)) -> 3.2 | G18: =IF($L18="","",INDEX(Плата!$S:$S,$L18)) -> 32 | H18: =IF($L18="","",INDEX(Плата!$Q:$Q,$L18)&"") -> в наявності | I18: =IF($L18="","",IF(INDEX(Плата!$AI:$AI,$L18)="","",HYPERLINK(INDEX(Плата!$AI:$AI,$L18),"відкрити"))) -> відкрити | J18: =IF($L18="","",INDEX(Плата!$U:$U,$L18)&"") -> IMRAD: «Є в наявності, на складі» (кількість не показано); ціна від 10 шт (1 шт: 3.72, від 50: 3.05). НЕ B2B-XH-AM (з бобишкою) | K18: =IFERROR(SMALL(Плата!$AJ$6:$AJ$44,14),"") -> 1021 | L18: =IF(K18="","",MOD(K18,1000)) -> 21
A19: =IF($L19="","",INDEX(Плата!$O:$O,$L19)&"") -> IMRAD | B19: =IF($L19="","",INDEX(Плата!$B:$B,$L19)&"") -> Q501 | C19: =IF($L19="","",INDEX(Плата!$P:$P,$L19)&"") -> Vishay SI2309CDS-T1-GE3 (точний MPN) | D19: =IF($L19="","",INDEX(Плата!$L:$L,$L19)) -> 10 | E19: =IF($L19="","",INDEX(Плата!$G:$G,$L19)&"") -> шт | F19: =IF($L19="","",INDEX(Плата!$R:$R,$L19)) -> 57.12 | G19: =IF($L19="","",INDEX(Плата!$S:$S,$L19)) -> 571.2 | H19: =IF($L19="","",INDEX(Плата!$Q:$Q,$L19)&"") -> в наявності | I19: =IF($L19="","",IF(INDEX(Плата!$AI:$AI,$L19)="","",HYPERLINK(INDEX(Плата!$AI:$AI,$L19),"відкрити"))) -> відкрити | J19: =IF($L19="","",INDEX(Плата!$U:$U,$L19)&"") -> IMRAD: «Є в наявності, на складі» (кількість не показано); одна ціна для будь-якої кількості | K19: =IFERROR(SMALL(Плата!$AJ$6:$AJ$44,15),"") -> 1023 | L19: =IF(K19="","",MOD(K19,1000)) -> 23
A20: =IF($L20="","",INDEX(Плата!$O:$O,$L20)&"") -> IMRAD | B20: =IF($L20="","",INDEX(Плата!$B:$B,$L20)&"") -> Q503 | C20: =IF($L20="","",INDEX(Плата!$P:$P,$L20)&"") -> onsemi MMBT5551LT1G (точний MPN) | D20: =IF($L20="","",INDEX(Плата!$L:$L,$L20)) -> 10 | E20: =IF($L20="","",INDEX(Плата!$G:$G,$L20)&"") -> шт | F20: =IF($L20="","",INDEX(Плата!$R:$R,$L20)) -> 1.62 | G20: =IF($L20="","",INDEX(Плата!$S:$S,$L20)) -> 16.2 | H20: =IF($L20="","",INDEX(Плата!$Q:$Q,$L20)&"") -> в наявності | I20: =IF($L20="","",IF(INDEX(Плата!$AI:$AI,$L20)="","",HYPERLINK(INDEX(Плата!$AI:$AI,$L20),"відкрити"))) -> відкрити | J20: =IF($L20="","",INDEX(Плата!$U:$U,$L20)&"") -> IMRAD: «Є в наявності, на складі» (кількість не показано); ціна від 10 шт (1 шт: 1.72, від 50: 1.54) | K20: =IFERROR(SMALL(Плата!$AJ$6:$AJ$44,16),"") -> 1024 | L20: =IF(K20="","",MOD(K20,1000)) -> 24
A21: =IF($L21="","",INDEX(Плата!$O:$O,$L21)&"") -> IMRAD | B21: =IF($L21="","",INDEX(Плата!$B:$B,$L21)&"") -> R101 | C21: =IF($L21="","",INDEX(Плата!$P:$P,$L21)&"") -> Yageo RC0603FR-0768KL (68 кОм 1 %), упаковка 100 шт | D21: =IF($L21="","",INDEX(Плата!$L:$L,$L21)) -> 100 | E21: =IF($L21="","",INDEX(Плата!$G:$G,$L21)&"") -> шт | F21: =IF($L21="","",INDEX(Плата!$R:$R,$L21)) -> 0.104 | G21: =IF($L21="","",INDEX(Плата!$S:$S,$L21)) -> 10.4 | H21: =IF($L21="","",INDEX(Плата!$Q:$Q,$L21)&"") -> в наявності | I21: =IF($L21="","",IF(INDEX(Плата!$AI:$AI,$L21)="","",HYPERLINK(INDEX(Плата!$AI:$AI,$L21),"відкрити"))) -> відкрити | J21: =IF($L21="","",INDEX(Плата!$U:$U,$L21)&"") -> IMRAD: «Є в наявності, на складі» (кількість не показано); 10.40 грн за 100 шт (від 5 уп.: 8.40, від 10: 7.00); ціна в рядку - за 1 шт | K21: =IFERROR(SMALL(Плата!$AJ$6:$AJ$44,17),"") -> 1025 | L21: =IF(K21="","",MOD(K21,1000)) -> 25
A22: =IF($L22="","",INDEX(Плата!$O:$O,$L22)&"") -> IMRAD | B22: =IF($L22="","",INDEX(Плата!$B:$B,$L22)&"") -> R102 | C22: =IF($L22="","",INDEX(Плата!$P:$P,$L22)&"") -> Royal Ohm 0603SAF5103T5E (510 кОм 1 %), упаковка 100 шт | D22: =IF($L22="","",INDEX(Плата!$L:$L,$L22)) -> 100 | E22: =IF($L22="","",INDEX(Плата!$G:$G,$L22)&"") -> шт | F22: =IF($L22="","",INDEX(Плата!$R:$R,$L22)) -> 0.117 | G22: =IF($L22="","",INDEX(Плата!$S:$S,$L22)) -> 11.7 | H22: =IF($L22="","",INDEX(Плата!$Q:$Q,$L22)&"") -> в наявності | I22: =IF($L22="","",IF(INDEX(Плата!$AI:$AI,$L22)="","",HYPERLINK(INDEX(Плата!$AI:$AI,$L22),"відкрити"))) -> відкрити | J22: =IF($L22="","",INDEX(Плата!$U:$U,$L22)&"") -> IMRAD: «Є в наявності, на складі» (кількість не показано); 11.70 грн за 100 шт (від 5 уп.: 9.45, від 10: 7.88); ціна в рядку - за 1 шт | K22: =IFERROR(SMALL(Плата!$AJ$6:$AJ$44,18),"") -> 1026 | L22: =IF(K22="","",MOD(K22,1000)) -> 26
A23: =IF($L23="","",INDEX(Плата!$O:$O,$L23)&"") -> IMRAD | B23: =IF($L23="","",INDEX(Плата!$B:$B,$L23)&"") -> R103 | C23: =IF($L23="","",INDEX(Плата!$P:$P,$L23)&"") -> Yageo RC0603FR-07220KL (220 кОм 1 %), упаковка 100 шт | D23: =IF($L23="","",INDEX(Плата!$L:$L,$L23)) -> 100 | E23: =IF($L23="","",INDEX(Плата!$G:$G,$L23)&"") -> шт | F23: =IF($L23="","",INDEX(Плата!$R:$R,$L23)) -> 0.262 | G23: =IF($L23="","",INDEX(Плата!$S:$S,$L23)) -> 26.2 | H23: =IF($L23="","",INDEX(Плата!$Q:$Q,$L23)&"") -> в наявності | I23: =IF($L23="","",IF(INDEX(Плата!$AI:$AI,$L23)="","",HYPERLINK(INDEX(Плата!$AI:$AI,$L23),"відкрити"))) -> відкрити | J23: =IF($L23="","",INDEX(Плата!$U:$U,$L23)&"") -> IMRAD: «Є в наявності, на складі» (кількість не показано); 26.20 грн за 100 шт (від 5 уп.: 25.20, від 10: 21.00); ціна в рядку - за 1 шт | K23: =IFERROR(SMALL(Плата!$AJ$6:$AJ$44,19),"") -> 1027 | L23: =IF(K23="","",MOD(K23,1000)) -> 27
A24: =IF($L24="","",INDEX(Плата!$O:$O,$L24)&"") -> IMRAD | B24: =IF($L24="","",INDEX(Плата!$B:$B,$L24)&"") -> R201, R202, R401, R501, R507 | C24: =IF($L24="","",INDEX(Плата!$P:$P,$L24)&"") -> Royal Ohm 0603SAF1002T5E (10 кОм 1 %), упаковка 100 шт | D24: =IF($L24="","",INDEX(Плата!$L:$L,$L24)) -> 100 | E24: =IF($L24="","",INDEX(Плата!$G:$G,$L24)&"") -> шт | F24: =IF($L24="","",INDEX(Плата!$R:$R,$L24)) -> 0.1404 | G24: =IF($L24="","",INDEX(Плата!$S:$S,$L24)) -> 14.04 | H24: =IF($L24="","",INDEX(Плата!$Q:$Q,$L24)&"") -> в наявності | I24: =IF($L24="","",IF(INDEX(Плата!$AI:$AI,$L24)="","",HYPERLINK(INDEX(Плата!$AI:$AI,$L24),"відкрити"))) -> відкрити | J24: =IF($L24="","",INDEX(Плата!$U:$U,$L24)&"") -> IMRAD: «Є в наявності, на складі» (кількість не показано); 14.04 грн за 100 шт (від 5 уп.: 11.34, від 10: 9.45); ціна в рядку - за 1 шт | K24: =IFERROR(SMALL(Плата!$AJ$6:$AJ$44,20),"") -> 1028 | L24: =IF(K24="","",MOD(K24,1000)) -> 28
A25: =IF($L25="","",INDEX(Плата!$O:$O,$L25)&"") -> IMRAD | B25: =IF($L25="","",INDEX(Плата!$B:$B,$L25)&"") -> R205, R206 | C25: =IF($L25="","",INDEX(Плата!$P:$P,$L25)&"") -> Yageo RC0603FR-075K1L (5.1 кОм 1 %), упаковка 100 шт | D25: =IF($L25="","",INDEX(Плата!$L:$L,$L25)) -> 100 | E25: =IF($L25="","",INDEX(Плата!$G:$G,$L25)&"") -> шт | F25: =IF($L25="","",INDEX(Плата!$R:$R,$L25)) -> 0.182 | G25: =IF($L25="","",INDEX(Плата!$S:$S,$L25)) -> 18.2 | H25: =IF($L25="","",INDEX(Плата!$Q:$Q,$L25)&"") -> в наявності | I25: =IF($L25="","",IF(INDEX(Плата!$AI:$AI,$L25)="","",HYPERLINK(INDEX(Плата!$AI:$AI,$L25),"відкрити"))) -> відкрити | J25: =IF($L25="","",INDEX(Плата!$U:$U,$L25)&"") -> IMRAD: «Є в наявності, на складі» (кількість не показано); 18.20 грн за 100 шт (від 5 уп.: 14.70, від 10: 12.25); ціна в рядку - за 1 шт | K25: =IFERROR(SMALL(Плата!$AJ$6:$AJ$44,21),"") -> 1029 | L25: =IF(K25="","",MOD(K25,1000)) -> 29
A26: =IF($L26="","",INDEX(Плата!$O:$O,$L26)&"") -> IMRAD | B26: =IF($L26="","",INDEX(Плата!$B:$B,$L26)&"") -> R208, R209 | C26: =IF($L26="","",INDEX(Плата!$P:$P,$L26)&"") -> Yageo RC0603FR-0722RL (22 Ом 1 %), упаковка 100 шт | D26: =IF($L26="","",INDEX(Плата!$L:$L,$L26)) -> 100 | E26: =IF($L26="","",INDEX(Плата!$G:$G,$L26)&"") -> шт | F26: =IF($L26="","",INDEX(Плата!$R:$R,$L26)) -> 0.208 | G26: =IF($L26="","",INDEX(Плата!$S:$S,$L26)) -> 20.8 | H26: =IF($L26="","",INDEX(Плата!$Q:$Q,$L26)&"") -> в наявності | I26: =IF($L26="","",IF(INDEX(Плата!$AI:$AI,$L26)="","",HYPERLINK(INDEX(Плата!$AI:$AI,$L26),"відкрити"))) -> відкрити | J26: =IF($L26="","",INDEX(Плата!$U:$U,$L26)&"") -> IMRAD: «Є в наявності, на складі» (кількість не показано); 20.80 грн за 100 шт (від 5 уп.: 16.80, від 10: 14.00); ціна в рядку - за 1 шт | K26: =IFERROR(SMALL(Плата!$AJ$6:$AJ$44,22),"") -> 1030 | L26: =IF(K26="","",MOD(K26,1000)) -> 30
A27: =IF($L27="","",INDEX(Плата!$O:$O,$L27)&"") -> IMRAD | B27: =IF($L27="","",INDEX(Плата!$B:$B,$L27)&"") -> R304 | C27: =IF($L27="","",INDEX(Плата!$P:$P,$L27)&"") -> Panasonic ERA-6AEB224V (220 кОм 0.1 % 25 ppm/K 0805, точний MPN) | D27: =IF($L27="","",INDEX(Плата!$L:$L,$L27)) -> 20 | E27: =IF($L27="","",INDEX(Плата!$G:$G,$L27)&"") -> шт | F27: =IF($L27="","",INDEX(Плата!$R:$R,$L27)) -> 5.12 | G27: =IF($L27="","",INDEX(Плата!$S:$S,$L27)) -> 102.4 | H27: =IF($L27="","",INDEX(Плата!$Q:$Q,$L27)&"") -> в наявності | I27: =IF($L27="","",IF(INDEX(Плата!$AI:$AI,$L27)="","",HYPERLINK(INDEX(Плата!$AI:$AI,$L27),"відкрити"))) -> відкрити | J27: =IF($L27="","",INDEX(Плата!$U:$U,$L27)&"") -> IMRAD: «Є в наявності, на складі» (кількість не показано); ціна від 10 шт (1 шт: 5.86) | K27: =IFERROR(SMALL(Плата!$AJ$6:$AJ$44,23),"") -> 1031 | L27: =IF(K27="","",MOD(K27,1000)) -> 31
A28: =IF($L28="","",INDEX(Плата!$O:$O,$L28)&"") -> IMRAD | B28: =IF($L28="","",INDEX(Плата!$B:$B,$L28)&"") -> R307, R502, R503, R510 | C28: =IF($L28="","",INDEX(Плата!$P:$P,$L28)&"") -> Yageo RC0603FR-071KL (1 кОм 1 %), упаковка 100 шт | D28: =IF($L28="","",INDEX(Плата!$L:$L,$L28)) -> 100 | E28: =IF($L28="","",INDEX(Плата!$G:$G,$L28)&"") -> шт | F28: =IF($L28="","",INDEX(Плата!$R:$R,$L28)) -> 0.1375 | G28: =IF($L28="","",INDEX(Плата!$S:$S,$L28)) -> 13.75 | H28: =IF($L28="","",INDEX(Плата!$Q:$Q,$L28)&"") -> в наявності | I28: =IF($L28="","",IF(INDEX(Плата!$AI:$AI,$L28)="","",HYPERLINK(INDEX(Плата!$AI:$AI,$L28),"відкрити"))) -> відкрити | J28: =IF($L28="","",INDEX(Плата!$U:$U,$L28)&"") -> IMRAD: «Є в наявності, на складі» (кількість не показано); 13.75 грн за 100 шт (від 5 уп.: 11.34, від 10: 9.45); ціна в рядку - за 1 шт | K28: =IFERROR(SMALL(Плата!$AJ$6:$AJ$44,24),"") -> 1033 | L28: =IF(K28="","",MOD(K28,1000)) -> 33
A29: =IF($L29="","",INDEX(Плата!$O:$O,$L29)&"") -> IMRAD | B29: =IF($L29="","",INDEX(Плата!$B:$B,$L29)&"") -> R504, R505 | C29: =IF($L29="","",INDEX(Плата!$P:$P,$L29)&"") -> Royal Ohm 0603SAF4701T5E (4.7 кОм 1 %; на сайті SMD0603-4K7-1%), упаковка 100 шт | D29: =IF($L29="","",INDEX(Плата!$L:$L,$L29)) -> 100 | E29: =IF($L29="","",INDEX(Плата!$G:$G,$L29)&"") -> шт | F29: =IF($L29="","",INDEX(Плата!$R:$R,$L29)) -> 0.1517 | G29: =IF($L29="","",INDEX(Плата!$S:$S,$L29)) -> 15.17 | H29: =IF($L29="","",INDEX(Плата!$Q:$Q,$L29)&"") -> в наявності | I29: =IF($L29="","",IF(INDEX(Плата!$AI:$AI,$L29)="","",HYPERLINK(INDEX(Плата!$AI:$AI,$L29),"відкрити"))) -> відкрити | J29: =IF($L29="","",INDEX(Плата!$U:$U,$L29)&"") -> IMRAD: «Є в наявності, на складі» (кількість не показано); 15.17 грн за 100 шт (від 5 уп.: 14.30, від 10: 13.50); ціна в рядку - за 1 шт | K29: =IFERROR(SMALL(Плата!$AJ$6:$AJ$44,25),"") -> 1034 | L29: =IF(K29="","",MOD(K29,1000)) -> 34
A30: =IF($L30="","",INDEX(Плата!$O:$O,$L30)&"") -> IMRAD | B30: =IF($L30="","",INDEX(Плата!$B:$B,$L30)&"") -> R506, R508, R509 | C30: =IF($L30="","",INDEX(Плата!$P:$P,$L30)&"") -> Yageo AC0603FR-07100KL (100 кОм 1 %), упаковка 100 шт | D30: =IF($L30="","",INDEX(Плата!$L:$L,$L30)) -> 100 | E30: =IF($L30="","",INDEX(Плата!$G:$G,$L30)&"") -> шт | F30: =IF($L30="","",INDEX(Плата!$R:$R,$L30)) -> 0.1808 | G30: =IF($L30="","",INDEX(Плата!$S:$S,$L30)) -> 18.08 | H30: =IF($L30="","",INDEX(Плата!$Q:$Q,$L30)&"") -> в наявності | I30: =IF($L30="","",IF(INDEX(Плата!$AI:$AI,$L30)="","",HYPERLINK(INDEX(Плата!$AI:$AI,$L30),"відкрити"))) -> відкрити | J30: =IF($L30="","",INDEX(Плата!$U:$U,$L30)&"") -> IMRAD: «Є в наявності, на складі» (кількість не показано); 18.08 грн за 100 шт (від 5 уп.: 17.68, від 10: 16.90); ціна в рядку - за 1 шт | K30: =IFERROR(SMALL(Плата!$AJ$6:$AJ$44,26),"") -> 1035 | L30: =IF(K30="","",MOD(K30,1000)) -> 35
A31: =IF($L31="","",INDEX(Плата!$O:$O,$L31)&"") -> IMRAD | B31: =IF($L31="","",INDEX(Плата!$B:$B,$L31)&"") -> R511 | C31: =IF($L31="","",INDEX(Плата!$P:$P,$L31)&"") -> Yageo RC2512JK-074R7L (4.7 Ом 5 % 2512 1 Вт, точний MPN) | D31: =IF($L31="","",INDEX(Плата!$L:$L,$L31)) -> 10 | E31: =IF($L31="","",INDEX(Плата!$G:$G,$L31)&"") -> шт | F31: =IF($L31="","",INDEX(Плата!$R:$R,$L31)) -> 1.34 | G31: =IF($L31="","",INDEX(Плата!$S:$S,$L31)) -> 13.4 | H31: =IF($L31="","",INDEX(Плата!$Q:$Q,$L31)&"") -> в наявності | I31: =IF($L31="","",IF(INDEX(Плата!$AI:$AI,$L31)="","",HYPERLINK(INDEX(Плата!$AI:$AI,$L31),"відкрити"))) -> відкрити | J31: =IF($L31="","",INDEX(Плата!$U:$U,$L31)&"") -> IMRAD: «Є в наявності, на складі» (кількість не показано); ціна від 10 шт (1 шт: 1.58, від 100: 1.04) | K31: =IFERROR(SMALL(Плата!$AJ$6:$AJ$44,27),"") -> 1036 | L31: =IF(K31="","",MOD(K31,1000)) -> 36
A32: =IF($L32="","",INDEX(Плата!$O:$O,$L32)&"") -> IMRAD | B32: =IF($L32="","",INDEX(Плата!$B:$B,$L32)&"") -> R512 | C32: =IF($L32="","",INDEX(Плата!$P:$P,$L32)&"") -> Royal Ohm 1206S4F1002T5E (10 кОм 1 % 1206), упаковка 100 шт | D32: =IF($L32="","",INDEX(Плата!$L:$L,$L32)) -> 100 | E32: =IF($L32="","",INDEX(Плата!$G:$G,$L32)&"") -> шт | F32: =IF($L32="","",INDEX(Плата!$R:$R,$L32)) -> 0.2808 | G32: =IF($L32="","",INDEX(Плата!$S:$S,$L32)) -> 28.08 | H32: =IF($L32="","",INDEX(Плата!$Q:$Q,$L32)&"") -> в наявності | I32: =IF($L32="","",IF(INDEX(Плата!$AI:$AI,$L32)="","",HYPERLINK(INDEX(Плата!$AI:$AI,$L32),"відкрити"))) -> відкрити | J32: =IF($L32="","",INDEX(Плата!$U:$U,$L32)&"") -> IMRAD: «Є в наявності, на складі» (кількість не показано); 28.08 грн за 100 шт (від 5 уп.: 22.68, від 10: 18.90); ціна в рядку - за 1 шт | K32: =IFERROR(SMALL(Плата!$AJ$6:$AJ$44,28),"") -> 1037 | L32: =IF(K32="","",MOD(K32,1000)) -> 37
A33: =IF($L33="","",INDEX(Плата!$O:$O,$L33)&"") -> IMRAD | B33: =IF($L33="","",INDEX(Плата!$B:$B,$L33)&"") -> U203 | C33: =IF($L33="","",INDEX(Плата!$P:$P,$L33)&"") -> ST USBLC6-2SC6 (точний MPN) | D33: =IF($L33="","",INDEX(Плата!$L:$L,$L33)) -> 10 | E33: =IF($L33="","",INDEX(Плата!$G:$G,$L33)&"") -> шт | F33: =IF($L33="","",INDEX(Плата!$R:$R,$L33)) -> 10.84 | G33: =IF($L33="","",INDEX(Плата!$S:$S,$L33)) -> 108.4 | H33: =IF($L33="","",INDEX(Плата!$Q:$Q,$L33)&"") -> в наявності | I33: =IF($L33="","",IF(INDEX(Плата!$AI:$AI,$L33)="","",HYPERLINK(INDEX(Плата!$AI:$AI,$L33),"відкрити"))) -> відкрити | J33: =IF($L33="","",INDEX(Плата!$U:$U,$L33)&"") -> IMRAD: «Є в наявності, на складі» (кількість не показано); ціна від 10 шт (1 шт: 11.50, від 35: 10.38) | K33: =IFERROR(SMALL(Плата!$AJ$6:$AJ$44,29),"") -> 1042 | L33: =IF(K33="","",MOD(K33,1000)) -> 42
A34: =IF($L34="","",INDEX(Плата!$O:$O,$L34)&"") -> VD MAIS | B34: =IF($L34="","",INDEX(Плата!$B:$B,$L34)&"") -> F501 | C34: =IF($L34="","",INDEX(Плата!$P:$P,$L34)&"") -> Littelfuse 0466.250NRHF (точний MPN), Digi-Key через VD MAIS | D34: =IF($L34="","",INDEX(Плата!$L:$L,$L34)) -> 10 | E34: =IF($L34="","",INDEX(Плата!$G:$G,$L34)&"") -> шт | F34: =IF($L34="","",INDEX(Плата!$R:$R,$L34)) -> 71.436 | G34: =IF($L34="","",INDEX(Плата!$S:$S,$L34)) -> 714.36 | H34: =IF($L34="","",INDEX(Плата!$Q:$Q,$L34)&"") -> під замовлення | I34: =IF($L34="","",IF(INDEX(Плата!$AI:$AI,$L34)="","",HYPERLINK(INDEX(Плата!$AI:$AI,$L34),"відкрити"))) -> відкрити | J34: =IF($L34="","",INDEX(Плата!$U:$U,$L34)&"") -> Digi-Key F5692CT-ND: 5812 шт, 3 тижні; ціна від 5 шт 59.53 грн без ПДВ (1 шт: 59.66), дані API VD MAIS; в IMRAD немає (0466.250NR - немає, 0451.250MRL - під замовлення). Замовляти разом з U101 | K34: =IFERROR(SMALL(Плата!$AJ$6:$AJ$44,30),"") -> 2017 | L34: =IF(K34="","",MOD(K34,1000)) -> 17
A35: =IF($L35="","",INDEX(Плата!$O:$O,$L35)&"") -> VD MAIS | B35: =IF($L35="","",INDEX(Плата!$B:$B,$L35)&"") -> L101 | C35: =IF($L35="","",INDEX(Плата!$P:$P,$L35)&"") -> Bourns SRN6045-220M (точний MPN) | D35: =IF($L35="","",INDEX(Плата!$L:$L,$L35)) -> 10 | E35: =IF($L35="","",INDEX(Плата!$G:$G,$L35)&"") -> шт | F35: =IF($L35="","",INDEX(Плата!$R:$R,$L35)) -> 12.27 | G35: =IF($L35="","",INDEX(Плата!$S:$S,$L35)) -> 122.7 | H35: =IF($L35="","",INDEX(Плата!$Q:$Q,$L35)&"") -> в наявності | I35: =IF($L35="","",IF(INDEX(Плата!$AI:$AI,$L35)="","",HYPERLINK(INDEX(Плата!$AI:$AI,$L35),"відкрити"))) -> відкрити | J35: =IF($L35="","",INDEX(Плата!$U:$U,$L35)&"") -> власний склад VD MAIS: 370 шт, строк 0 тижнів; в IMRAD 22 мкГн з Isat >= 1.6 А немає | K35: =IFERROR(SMALL(Плата!$AJ$6:$AJ$44,31),"") -> 2022 | L35: =IF(K35="","",MOD(K35,1000)) -> 22
A36: =IF($L36="","",INDEX(Плата!$O:$O,$L36)&"") -> VD MAIS | B36: =IF($L36="","",INDEX(Плата!$B:$B,$L36)&"") -> R305 | C36: =IF($L36="","",INDEX(Плата!$P:$P,$L36)&"") -> Yageo RT0603BRD0710KL (точний MPN) | D36: =IF($L36="","",INDEX(Плата!$L:$L,$L36)) -> 10 | E36: =IF($L36="","",INDEX(Плата!$G:$G,$L36)&"") -> шт | F36: =IF($L36="","",INDEX(Плата!$R:$R,$L36)) -> 2.07 | G36: =IF($L36="","",INDEX(Плата!$S:$S,$L36)) -> 20.7 | H36: =IF($L36="","",INDEX(Плата!$Q:$Q,$L36)&"") -> в наявності | I36: =IF($L36="","",IF(INDEX(Плата!$AI:$AI,$L36)="","",HYPERLINK(INDEX(Плата!$AI:$AI,$L36),"відкрити"))) -> відкрити | J36: =IF($L36="","",INDEX(Плата!$U:$U,$L36)&"") -> власний склад VD MAIS: 50 шт, строк 0 тижнів; ціна від 10 шт. В IMRAD лише 10.2 кОм 0.1 % (змінило б коефіцієнт дільника) | K36: =IFERROR(SMALL(Плата!$AJ$6:$AJ$44,32),"") -> 2032 | L36: =IF(K36="","",MOD(K36,1000)) -> 32
A37: =IF($L37="","",INDEX(Плата!$O:$O,$L37)&"") -> VD MAIS | B37: =IF($L37="","",INDEX(Плата!$B:$B,$L37)&"") -> U101 | C37: =IF($L37="","",INDEX(Плата!$P:$P,$L37)&"") -> TI LMR38010SQDDARQ1 (Q1-версія LMR38010SDDAR), Digi-Key через VD MAIS | D37: =IF($L37="","",INDEX(Плата!$L:$L,$L37)) -> 6 | E37: =IF($L37="","",INDEX(Плата!$G:$G,$L37)&"") -> шт | F37: =IF($L37="","",INDEX(Плата!$R:$R,$L37)) -> 302.184 | G37: =IF($L37="","",INDEX(Плата!$S:$S,$L37)) -> 1813.104 | H37: =IF($L37="","",INDEX(Плата!$Q:$Q,$L37)&"") -> під замовлення | I37: =IF($L37="","",IF(INDEX(Плата!$AI:$AI,$L37)="","",HYPERLINK(INDEX(Плата!$AI:$AI,$L37),"відкрити"))) -> відкрити | J37: =IF($L37="","",INDEX(Плата!$U:$U,$L37)&"") -> Digi-Key 296-LMR38010SQDDARQ1CT-ND: 2220 шт, 3 тижні; 251.82 грн без ПДВ (від 10: 225.26), дані API VD MAIS. В IMRAD немає. Замовляти зараз разом з F501 і U301 | K37: =IFERROR(SMALL(Плата!$AJ$6:$AJ$44,33),"") -> 2039 | L37: =IF(K37="","",MOD(K37,1000)) -> 39
A38: =IF($L38="","",INDEX(Плата!$O:$O,$L38)&"") -> VD MAIS | B38: =IF($L38="","",INDEX(Плата!$B:$B,$L38)&"") -> U202 | C38: =IF($L38="","",INDEX(Плата!$P:$P,$L38)&"") -> TI TPS3808G33DBVR (точний MPN) | D38: =IF($L38="","",INDEX(Плата!$L:$L,$L38)) -> 6 | E38: =IF($L38="","",INDEX(Плата!$G:$G,$L38)&"") -> шт | F38: =IF($L38="","",INDEX(Плата!$R:$R,$L38)) -> 84.42 | G38: =IF($L38="","",INDEX(Плата!$S:$S,$L38)) -> 506.52 | H38: =IF($L38="","",INDEX(Плата!$Q:$Q,$L38)&"") -> в наявності | I38: =IF($L38="","",IF(INDEX(Плата!$AI:$AI,$L38)="","",HYPERLINK(INDEX(Плата!$AI:$AI,$L38),"відкрити"))) -> відкрити | J38: =IF($L38="","",INDEX(Плата!$U:$U,$L38)&"") -> власний склад VD MAIS: 227 шт, строк 0 тижнів | K38: =IFERROR(SMALL(Плата!$AJ$6:$AJ$44,34),"") -> 2041 | L38: =IF(K38="","",MOD(K38,1000)) -> 41
A39: =IF($L39="","",INDEX(Плата!$O:$O,$L39)&"") -> VD MAIS | B39: =IF($L39="","",INDEX(Плата!$B:$B,$L39)&"") -> U301 | C39: =IF($L39="","",INDEX(Плата!$P:$P,$L39)&"") -> TI ADS1115IDGSR: 4 шт власний склад VD MAIS + 2 шт Digi-Key через VD MAIS | D39: =IF($L39="","",INDEX(Плата!$L:$L,$L39)) -> 6 | E39: =IF($L39="","",INDEX(Плата!$G:$G,$L39)&"") -> шт | F39: =IF($L39="","",INDEX(Плата!$R:$R,$L39)) -> 282.01 | G39: =IF($L39="","",INDEX(Плата!$S:$S,$L39)) -> 1692.06 | H39: =IF($L39="","",INDEX(Плата!$Q:$Q,$L39)&"") -> в наявності | I39: =IF($L39="","",IF(INDEX(Плата!$AI:$AI,$L39)="","",HYPERLINK(INDEX(Плата!$AI:$AI,$L39),"відкрити"))) -> відкрити | J39: =IF($L39="","",INDEX(Плата!$U:$U,$L39)&"") -> власний склад: 4 шт по 198.23 грн, строк 0 тижнів; решта 2 шт - Digi-Key 296-38849-1-ND (34304 шт, 3 тижні, 374.63 грн без ПДВ = 449.56 з ПДВ) у тому ж кошику VD MAIS. Ціна в рядку - середня для 6 шт ((4 x 198.23 + 2 x 449.56) / 6 = 282.01); для іншої кількості перерахувати | K39: =IFERROR(SMALL(Плата!$AJ$6:$AJ$44,35),"") -> 2043 | L39: =IF(K39="","",MOD(K39,1000)) -> 43
A40: =IF($L40="","",INDEX(Плата!$O:$O,$L40)&"") | B40: =IF($L40="","",INDEX(Плата!$B:$B,$L40)&"") | C40: =IF($L40="","",INDEX(Плата!$P:$P,$L40)&"") | D40: =IF($L40="","",INDEX(Плата!$L:$L,$L40)) | E40: =IF($L40="","",INDEX(Плата!$G:$G,$L40)&"") | F40: =IF($L40="","",INDEX(Плата!$R:$R,$L40)) | G40: =IF($L40="","",INDEX(Плата!$S:$S,$L40)) | H40: =IF($L40="","",INDEX(Плата!$Q:$Q,$L40)&"") | I40: =IF($L40="","",IF(INDEX(Плата!$AI:$AI,$L40)="","",HYPERLINK(INDEX(Плата!$AI:$AI,$L40),"відкрити"))) | J40: =IF($L40="","",INDEX(Плата!$U:$U,$L40)&"") | K40: =IFERROR(SMALL(Плата!$AJ$6:$AJ$44,36),"") | L40: =IF(K40="","",MOD(K40,1000))
...

Sheet Плата
A1: Аркуш «Плата»: один рядок = одна група однакових деталей з KiCad BOM плати battery-monitor-rev-a. Результат - стовпець «ЗАМОВИТИ» і аркуш «Список покупок».
A2: Змінювати можна лише ЖОВТІ клітинки: «Купити щонайменше» - скільки взяти із запасом для інших плат; «Вже є» - що вже лежить у вас (наприклад, залишок після rev-c: стовпець «Деталь з rev-c»); «Джерело» і «Магазин» - звідки брати.
A3: «Потрібно на всі плати» + «на брак» → «ЗАМОВИТИ» (не менше «Купити щонайменше» і мінімального замовлення магазину) → «Лишиться в запасі». Технічні стовпці (ціна на сайті, мінімум, резерв, MPN) згорнуто: кнопка «+» над заголовками.
A4: ДЕТАЛЬ | F4: СКІЛЬКИ | N4: ДЕ КУПИТИ | V4: ДОВІДКА (згорнуто: «+» над стовпцями)
A5: № | B5: Позиції | C5: Номінал | D5: Корпус (KiCad footprint) | E5: Що купувати / допустима заміна | F5: На 1 плату | G5: Од. | H5: Потрібно на всі плати | I5: + на брак | J5: Купити щонайменше ✎ | K5: Вже є ✎ | L5: ЗАМОВИТИ | M5: Лишиться в запасі | N5: Джерело ✎ | O5: Магазин ✎ | P5: Що саме замовити | Q5: Статус | R5: Ціна з ПДВ, грн/од. | S5: Сума, грн | T5: Посилання | U5: Примітка до покупки | V5: Ціна на сайті, грн/од. | W5: Ціна вказана | X5: Мін. замовл. | Y5: Кратність | Z5: Відповідність | AA5: Перевірено | AB5: Резервний варіант | AC5: Резерв: посилання | AD5: AliExpress (пошук) | AE5: Деталь з rev-c | AF5: Категорія | AG5: Призначення в схемі | AH5: MPN у KiCad (виробник) | AI5: URL (службовий) | AJ5: Ключ (службовий)
A6: 1 | B6: C101 | C6: 22uF 100V | D6: CP_Elec_8x10 | E6: 22 мкФ 100 В, алюмінієвий SMD 8x10 мм, low-ESR (Panasonic FK або аналог того самого розміру) | F6: 1 | G6: шт | H6: =F6*Інструкція!$C$5 -> 5 | I6: =IF(H6=0,0,MAX(ROUNDUP(H6*INDEX(Інструкція!$C$9:$C$13,MATCH(AF6,Інструкція!$B$9:$B$13,0)),0),INDEX(Інструкція!$D$9:$D$13,MATCH(AF6,Інструкція!$B$9:$B$13,0)))) -> 3 | J6: 10 | K6: 0 | L6: =IF(N6<>"магазин",0,IF(MAX(0,MAX(H6+I6,J6)-K6)=0,0,MAX(X6,CEILING(MAX(0,MAX(H6+I6,J6)-K6),Y6)))) -> 10 | M6: =IF(N6="магазин",L6+K6-H6,IF(N6="книга резисторів 0603",(Набори!$D$5+Набори!$E$5)*Набори!$F$5-H6,"")) -> 5 | N6: магазин | O6: IMRAD | P6: Panasonic EEEFK2A220P (точний MPN) | Q6: в наявності | R6: =IF(V6="","",IF(W6="без ПДВ",V6*(1+Інструкція!$C$6),V6)) -> 14.82 | S6: =IF(L6=0,0,IF(R6="","",L6*R6)) -> 148.2 | T6: відкрити | U6: IMRAD: «Є в наявності, на складі» (кількість не показано); ціна від 6 шт (1 шт: 16.13, від 15: 13.69, від 70: 12.38) | V6: 14.82 | W6: як на сторінці | X6: 1 | Y6: 1 | Z6: точний MPN | AA6: 2026-10-25 | AB6: Космодром: Panasonic EEEFK2A220P (точний MPN): в наявності, 14.5 грн (без ПДВ). на складі 131 шт | AC6: відкрити | AD6: пошук | AF6: Дрібні пасивні | AG6: C101: демпфування дзвону на проводах батареї (VIN_PROT) | AH6: EEE-FK2A220P (Panasonic) | AI6: https://imrad.com.ua/ua/eeefk2a220p-3 | AJ6: =IF(L6>0,IFERROR(MATCH(O6,Кошики!$A$2:$A$10,0),99)*1000+ROW(),"") -> 1006
A7: 2 | B7: C102 | C7: 10uF 100V | D7: C_1210_3225Metric | E7: 10 мкФ 100 В X7S 1210, Murata GRM32EC72A106KE05L (той самий з кодом пакування KE05K; допустима заміна Samsung CL32Y106KCVZ4NE) | F7: 1 | G7: шт | H7: =F7*Інструкція!$C$5 -> 5 | I7: =IF(H7=0,0,MAX(ROUNDUP(H7*INDEX(Інструкція!$C$9:$C$13,MATCH(AF7,Інструкція!$B$9:$B$13,0)),0),INDEX(Інструкція!$D$9:$D$13,MATCH(AF7,Інструкція!$B$9:$B$13,0)))) -> 3 | J7: 10 | K7: 0 | L7: =IF(N7<>"магазин",0,IF(MAX(0,MAX(H7+I7,J7)-K7)=0,0,MAX(X7,CEILING(MAX(0,MAX(H7+I7,J7)-K7),Y7)))) -> 10 | M7: =IF(N7="магазин",L7+K7-H7,IF(N7="книга резисторів 0603",(Набори!$D$5+Набори!$E$5)*Набори!$F$5-H7,"")) -> 5 | N7: магазин | O7: IMRAD | P7: Murata GRM32EC72A106KE05L (точний MPN) | Q7: в наявності | R7: =IF(V7="","",IF(W7="без ПДВ",V7*(1+Інструкція!$C$6),V7)) -> 32.06 | S7: =IF(L7=0,0,IF(R7="","",L7*R7)) -> 320.6 | T7: відкрити | U7: IMRAD: «Є в наявності, на складі» (кількість не показано); ціна від 5 шт (1 шт: 36.53) | V7: 32.06 | W7: як на сторінці | X7: 1 | Y7: 1 | Z7: точний MPN | AA7: 2026-10-25 | AB7: VD MAIS: Murata GRM32EC72A106KE05K (10 мкФ 100 В X7S 1210): в наявності, 44.55 грн (з ПДВ). той самий GRM32EC72A106KE05L, інший лише код пакування; на складі 60 шт | AC7: відкрити | AD7: пошук | AF7: Дрібні пасивні | AG7: C102: вхідний конденсатор U101 LMR38010 | AH7: GRM32EC72A106KE05L (Murata) | AI7: https://imrad.com.ua/ua/grm32ec72a106ke05l-2 | AJ7: =IF(L7>0,IFERROR(MATCH(O7,Кошики!$A$2:$A$10,0),99)*1000+ROW(),"") -> 1007
A8: 3 | B8: C103 | C8: 100nF 100V | D8: C_0603_1608Metric | E8: 100 нФ, 0603, X7R, >= 100 В (Samsung CL10B104KC8NNNC або аналог X7R 100 В) | F8: 1 | G8: шт | H8: =F8*Інструкція!$C$5 -> 5 | I8: =IF(H8=0,0,MAX(ROUNDUP(H8*INDEX(Інструкція!$C$9:$C$13,MATCH(AF8,Інструкція!$B$9:$B$13,0)),0),INDEX(Інструкція!$D$9:$D$13,MATCH(AF8,Інструкція!$B$9:$B$13,0)))) -> 3 | J8: 100 | K8: 0 | L8: =IF(N8<>"магазин",0,IF(MAX(0,MAX(H8+I8,J8)-K8)=0,0,MAX(X8,CEILING(MAX(0,MAX(H8+I8,J8)-K8),Y8)))) -> 100 | M8: =IF(N8="магазин",L8+K8-H8,IF(N8="книга резисторів 0603",(Набори!$D$5+Набори!$E$5)*Набори!$F$5-H8,"")) -> 95 | N8: магазин | O8: IMRAD | P8: Samsung CL10B104KC8NNNC (100 нФ X7R 100 В 0603, точний MPN) | Q8: в наявності | R8: =IF(V8="","",IF(W8="без ПДВ",V8*(1+Інструкція!$C$6),V8)) -> 0.94 | S8: =IF(L8=0,0,IF(R8="","",L8*R8)) -> 94 | T8: відкрити | U8: IMRAD: «Є в наявності, на складі» (кількість не показано); ціна від 100 шт (1 шт: 1.65, від 10: 1.02) | V8: 0.94 | W8: як на сторінці | X8: 1 | Y8: 1 | Z8: точний MPN | AA8: 2026-10-25 | AB8: Космодром: Samsung CL10B104KC8NNNC (точний MPN), партнерський склад: під замовлення, 2.76 грн (без ПДВ), мін. 50 шт. 4-6 тижнів, ціна від 50 шт | AC8: відкрити | AD8: пошук | AF8: Дрібні пасивні | AG8: C103: розв'язка VIN/GND біля U101 | AH8: CL10B104KC8NNNC (Samsung) | AI8: https://imrad.com.ua/ua/cl10b104kc8nnnc-3 | AJ8: =IF(L8>0,IFERROR(MATCH(O8,Кошики!$A$2:$A$10,0),99)*1000+ROW(),"") -> 1008
A9: 4 | B9: C104, C202-C205, C301, C302, C402 | C9: 100nF | D9: C_0603_1608Metric | E9: 100 нФ, 0603, X7R, >= 25 В (C104 bootstrap >= 16 В): Samsung CL10B104KB8NNNC (50 В) | F9: 8 | G9: шт | H9: =F9*Інструкція!$C$5 -> 40 | I9: =IF(H9=0,0,MAX(ROUNDUP(H9*INDEX(Інструкція!$C$9:$C$13,MATCH(AF9,Інструкція!$B$9:$B$13,0)),0),INDEX(Інструкція!$D$9:$D$13,MATCH(AF9,Інструкція!$B$9:$B$13,0)))) -> 8 | J9: 100 | K9: 0 | L9: =IF(N9<>"магазин",0,IF(MAX(0,MAX(H9+I9,J9)-K9)=0,0,MAX(X9,CEILING(MAX(0,MAX(H9+I9,J9)-K9),Y9)))) -> 100 | M9: =IF(N9="магазин",L9+K9-H9,IF(N9="книга резисторів 0603",(Набори!$D$5+Набори!$E$5)*Набори!$F$5-H9,"")) -> 60 | N9: магазин | O9: IMRAD | P9: Samsung CL10B104KB8NNNC (100 нФ X7R 50 В 0603, точний MPN) | Q9: в наявності | R9: =IF(V9="","",IF(W9="без ПДВ",V9*(1+Інструкція!$C$6),V9)) -> 0.67 | S9: =IF(L9=0,0,IF(R9="","",L9*R9)) -> 67 | T9: відкрити | U9: IMRAD: «Є в наявності, на складі» (кількість не показано); ціна від 100 шт (1 шт: 1.65, від 10: 0.72, від 500: 0.63) | V9: 0.67 | W9: як на сторінці | X9: 1 | Y9: 1 | Z9: точний MPN | AA9: 2026-10-25 | AB9: Космодром: Samsung CL10B104KB8NNNC (точний MPN), партнерський склад: під замовлення, 1.79 грн (без ПДВ), мін. 100 шт. 4-6 тижнів, ціна від 100 шт | AC9: відкрити | AD9: пошук | AF9: Дрібні пасивні | AG9: C104 bootstrap U101; C202-C205 розв'язка ESP32; C301/C302 ADS1115 і RC-фільтр AIN0; C402 Ra-02 | AH9: CL10B104KB8NNNC (Samsung) | AI9: https://imrad.com.ua/ua/cl10b104kb8nnnc-8 | AJ9: =IF(L9>0,IFERROR(MATCH(O9,Кошики!$A$2:$A$10,0),99)*1000+ROW(),"") -> 1009
A10: 5 | B10: C105-C107, C201 | C10: 22uF | D10: C_0805_2012Metric | E10: 22 мкФ, 0805, X5R, >= 25 В: Murata GRM21BR61E226ME44L (або Samsung CL21A226MAYNNNE того самого класу) | F10: 4 | G10: шт | H10: =F10*Інструкція!$C$5 -> 20 | I10: =IF(H10=0,0,MAX(ROUNDUP(H10*INDEX(Інструкція!$C$9:$C$13,MATCH(AF10,Інструкція!$B$9:$B$13,0)),0),INDEX(Інструкція!$D$9:$D$13,MATCH(AF10,Інструкція!$B$9:$B$13,0)))) -> 4 | J10: 50 | K10: 0 | L10: =IF(N10<>"магазин",0,IF(MAX(0,MAX(H10+I10,J10)-K10)=0,0,MAX(X10,CEILING(MAX(0,MAX(H10+I10,J10)-K10),Y10)))) -> 50 | M10: =IF(N10="магазин",L10+K10-H10,IF(N10="книга резисторів 0603",(Набори!$D$5+Набори!$E$5)*Набори!$F$5-H10,"")) -> 30 | N10: магазин | O10: IMRAD | P10: Murata GRM21BR61E226ME44L (точний MPN) | Q10: в наявності | R10: =IF(V10="","",IF(W10="без ПДВ",V10*(1+Інструкція!$C$6),V10)) -> 12.04 | S10: =IF(L10=0,0,IF(R10="","",L10*R10)) -> 602 | T10: відкрити | U10: IMRAD: «Є в наявності, на складі» (кількість не показано); ціна від 10 шт (1 шт: 13.42, від 100: 11.21). «Купити щонайменше» 50 задано, коли ціна була 2.96 грн: потреба 5 плат = 24 шт | V10: 12.04 | W10: як на сторінці | X10: 1 | Y10: 1 | Z10: точний MPN | AA10: 2026-10-25 | AB10: Космодром: Murata GRM21BR61E226ME44L (точний MPN), партнерський склад: під замовлення, 32.83 грн (без ПДВ), мін. 5 шт. 4-6 тижнів, ціна від 5 шт | AC10: відкрити | AD10: пошук | AF10: Дрібні пасивні | AG10: C105-C107: вихід buck +3V3; C201: +3V3 біля ESP32 | AH10: GRM21BR61E226ME44L (Murata) | AI10: https://imrad.com.ua/ua/grm21br61e226me44l-1 | AJ10: =IF(L10>0,IFERROR(MATCH(O10,Кошики!$A$2:$A$10,0),99)*1000+ROW(),"") -> 1010
A11: 6 | B11: C401 | C11: 10uF | D11: C_0805_2012Metric | E11: 10 мкФ, 0805, X5R або X7R, >= 10 В | F11: 1 | G11: шт | H11: =F11*Інструкція!$C$5 -> 5 | I11: =IF(H11=0,0,MAX(ROUNDUP(H11*INDEX(Інструкція!$C$9:$C$13,MATCH(AF11,Інструкція!$B$9:$B$13,0)),0),INDEX(Інструкція!$D$9:$D$13,MATCH(AF11,Інструкція!$B$9:$B$13,0)))) -> 3 | J11: 20 | K11: 0 | L11: =IF(N11<>"магазин",0,IF(MAX(0,MAX(H11+I11,J11)-K11)=0,0,MAX(X11,CEILING(MAX(0,MAX(H11+I11,J11)-K11),Y11)))) -> 20 | M11: =IF(N11="магазин",L11+K11-H11,IF(N11="книга резисторів 0603",(Набори!$D$5+Набори!$E$5)*Набори!$F$5-H11,"")) -> 15 | N11: магазин | O11: IMRAD | P11: Samsung CL21A106KAYNNNE (точний MPN) | Q11: в наявності | R11: =IF(V11="","",IF(W11="без ПДВ",V11*(1+Інструкція!$C$6),V11)) -> 3.41 | S11: =IF(L11=0,0,IF(R11="","",L11*R11)) -> 68.2 | T11: відкрити | U11: IMRAD: «Є в наявності, на складі» (кількість не показано); ціна від 10 шт (1 шт: 3.80, від 100: 3.18) | V11: 3.41 | W11: як на сторінці | X11: 1 | Y11: 1 | Z11: точний MPN | AA11: 2026-10-25 | AB11: VD MAIS: Samsung CL21A106KAYNNNE (точний MPN): в наявності, 0.92 грн (з ПДВ), мін. 10 шт. ціна від 10 шт; на складі 1293 шт | AC11: відкрити | AD11: пошук | AE11: так | AF11: Дрібні пасивні | AG11: C401: +3V3 біля Ra-02 | AH11: CL21A106KAYNNNE (Samsung) | AI11: https://imrad.com.ua/ua/cl21a106kaynnne-3 | AJ11: =IF(L11>0,IFERROR(MATCH(O11,Кошики!$A$2:$A$10,0),99)*1000+ROW(),"") -> 1011
A12: 7 | B12: D101 | C12: B1100 | D12: D_SMA | E12: Шотткі 100 В 1 А, SMA: Diodes B1100-13-F (VF 0.79 В max при 1 А). НЕ ставити 60-вольтові SS1x (SS16 тощо) | F12: 1 | G12: шт | H12: =F12*Інструкція!$C$5 -> 5 | I12: =IF(H12=0,0,MAX(ROUNDUP(H12*INDEX(Інструкція!$C$9:$C$13,MATCH(AF12,Інструкція!$B$9:$B$13,0)),0),INDEX(Інструкція!$D$9:$D$13,MATCH(AF12,Інструкція!$B$9:$B$13,0)))) -> 1 | J12: 10 | K12: 0 | L12: =IF(N12<>"магазин",0,IF(MAX(0,MAX(H12+I12,J12)-K12)=0,0,MAX(X12,CEILING(MAX(0,MAX(H12+I12,J12)-K12),Y12)))) -> 10 | M12: =IF(N12="магазин",L12+K12-H12,IF(N12="книга резисторів 0603",(Набори!$D$5+Набори!$E$5)*Набори!$F$5-H12,"")) -> 5 | N12: магазин | O12: IMRAD | P12: Diodes B1100-13-F (100 В, 1 А, SMA, точний MPN) | Q12: в наявності | R12: =IF(V12="","",IF(W12="без ПДВ",V12*(1+Інструкція!$C$6),V12)) -> 5.55 | S12: =IF(L12=0,0,IF(R12="","",L12*R12)) -> 55.5 | T12: відкрити | U12: IMRAD: «Є в наявності, на складі» (кількість не показано); ціна від 10 шт (1 шт: 6.07, від 50: 5.21) | V12: 5.55 | W12: як на сторінці | X12: 1 | Y12: 1 | Z12: точний MPN | AA12: 2026-10-25 | AB12: Космодром: Diodes B1100-13-F (точний MPN): в наявності, 3 грн (без ПДВ). на складі 1475 шт | AC12: відкрити | AD12: пошук | AF12: Мікросхеми та силові | AG12: D101: захист від переполюсовки батареї | AH12: B1100-13-F (Diodes Incorporated) | AI12: https://imrad.com.ua/ua/b1100-13-f-9 | AJ12: =IF(L12>0,IFERROR(MATCH(O12,Кошики!$A$2:$A$10,0),99)*1000+ROW(),"") -> 1012
A13: 8 | B13: D102 | C13: SMAJ33A | D13: D_SMA | E13: SMAJ33A будь-якого виробника: 33 В, 400 Вт, ОДНОНАПРЯМЛЕНИЙ (не SMAJ33CA), SMA | F13: 1 | G13: шт | H13: =F13*Інструкція!$C$5 -> 5 | I13: =IF(H13=0,0,MAX(ROUNDUP(H13*INDEX(Інструкція!$C$9:$C$13,MATCH(AF13,Інструкція!$B$9:$B$13,0)),0),INDEX(Інструкція!$D$9:$D$13,MATCH(AF13,Інструкція!$B$9:$B$13,0)))) -> 1 | J13: 10 | K13: 0 | L13: =IF(N13<>"магазин",0,IF(MAX(0,MAX(H13+I13,J13)-K13)=0,0,MAX(X13,CEILING(MAX(0,MAX(H13+I13,J13)-K13),Y13)))) -> 10 | M13: =IF(N13="магазин",L13+K13-H13,IF(N13="книга резисторів 0603",(Набори!$D$5+Набори!$E$5)*Набори!$F$5-H13,"")) -> 5 | N13: магазин | O13: IMRAD | P13: ST SMAJ33A-TR (однонаправлений, 33 В, 400 Вт, SMA, точний MPN) | Q13: в наявності | R13: =IF(V13="","",IF(W13="без ПДВ",V13*(1+Інструкція!$C$6),V13)) -> 6.26 | S13: =IF(L13=0,0,IF(R13="","",L13*R13)) -> 62.6 | T13: відкрити | U13: IMRAD: «Є в наявності, на складі» (кількість не показано); ціна від 10 шт (1 шт: 6.85, від 50: 5.87) | V13: 6.26 | W13: як на сторінці | X13: 1 | Y13: 1 | Z13: точний MPN | AA13: 2026-10-25 | AB13: Космодром: ST SMAJ33A-TR (точний MPN), партнерський склад: під замовлення, 9.52 грн (без ПДВ), мін. 5 шт. 4-6 тижнів, ціна від 5 шт (власний склад Космодрому: 0 шт, очікується) | AC13: відкрити | AD13: пошук | AF13: Мікросхеми та силові | AG13: D102: TVS на вході VIN_PROT | AH13: SMAJ33A-TR (STMicroelectronics) | AI13: https://imrad.com.ua/ua/smaj33a-tr-4 | AJ13: =IF(L13>0,IFERROR(MATCH(O13,Кошики!$A$2:$A$10,0),99)*1000+ROW(),"") -> 1013
A14: 9 | B14: D501 | C14: GREEN | D14: LED_0603_1608Metric | E14: Жовто-зелений світлодіод 0603, Vf близько 2.0-2.4 В (571 нм): Lite-On LTST-C191KGKT. НЕ ставити смарагдові 525 нм / 3 В | F14: 1 | G14: шт | H14: =F14*Інструкція!$C$5 -> 5 | I14: =IF(H14=0,0,MAX(ROUNDUP(H14*INDEX(Інструкція!$C$9:$C$13,MATCH(AF14,Інструкція!$B$9:$B$13,0)),0),INDEX(Інструкція!$D$9:$D$13,MATCH(AF14,Інструкція!$B$9:$B$13,0)))) -> 3 | J14: 20 | K14: 0 | L14: =IF(N14<>"магазин",0,IF(MAX(0,MAX(H14+I14,J14)-K14)=0,0,MAX(X14,CEILING(MAX(0,MAX(H14+I14,J14)-K14),Y14)))) -> 20 | M14: =IF(N14="магазин",L14+K14-H14,IF(N14="книга резисторів 0603",(Набори!$D$5+Набори!$E$5)*Набори!$F$5-H14,"")) -> 15 | N14: магазин | O14: IMRAD | P14: Lite-On LTST-C191KGKT (жовто-зелений 571 нм, точний MPN) | Q14: в наявності | R14: =IF(V14="","",IF(W14="без ПДВ",V14*(1+Інструкція!$C$6),V14)) -> 1.74 | S14: =IF(L14=0,0,IF(R14="","",L14*R14)) -> 34.8 | T14: відкрити | U14: IMRAD: «Є в наявності, на складі» (кількість не показано); ціна від 10 шт (1 шт: 1.84, від 50: 1.56) | V14: 1.74 | W14: як на сторінці | X14: 1 | Y14: 1 | Z14: точний MPN | AA14: 2026-10-25 | AB14: Космодром: Lite-On LTST-C191KGKT (точний MPN), партнерський склад: під замовлення, 2 грн (без ПДВ), мін. 50 шт. 4-6 тижнів, ціна від 50 шт | AC14: відкрити | AD14: пошук | AF14: Дрібні пасивні | AG14: D501: STATUS (GPIO40) | AH14: LTST-C191KGKT (Lite-On) | AI14: https://imrad.com.ua/ua/ltst-c191kgkt-4 | AJ14: =IF(L14>0,IFERROR(MATCH(O14,Кошики!$A$2:$A$10,0),99)*1000+ROW(),"") -> 1014
A15: 10 | B15: D502 | C15: RED | D15: LED_0603_1608Metric | E15: Червоний світлодіод 0603, 630 нм, Vf близько 2 В: Kingbright KP-1608SURCK | F15: 1 | G15: шт | H15: =F15*Інструкція!$C$5 -> 5 | I15: =IF(H15=0,0,MAX(ROUNDUP(H15*INDEX(Інструкція!$C$9:$C$13,MATCH(AF15,Інструкція!$B$9:$B$13,0)),0),INDEX(Інструкція!$D$9:$D$13,MATCH(AF15,Інструкція!$B$9:$B$13,0)))) -> 3 | J15: 20 | K15: 0 | L15: =IF(N15<>"магазин",0,IF(MAX(0,MAX(H15+I15,J15)-K15)=0,0,MAX(X15,CEILING(MAX(0,MAX(H15+I15,J15)-K15),Y15)))) -> 20 | M15: =IF(N15="магазин",L15+K15-H15,IF(N15="книга резисторів 0603",(Набори!$D$5+Набори!$E$5)*Набори!$F$5-H15,"")) -> 15 | N15: магазин | O15: IMRAD | P15: Kingbright KP-1608SURCK (червоний 630 нм, точний MPN) | Q15: в наявності | R15: =IF(V15="","",IF(W15="без ПДВ",V15*(1+Інструкція!$C$6),V15)) -> 4.69 | S15: =IF(L15=0,0,IF(R15="","",L15*R15)) -> 93.8 | T15: відкрити | U15: IMRAD: «Є в наявності, на складі» (кількість не показано); ціна від 10 шт (1 шт: 4.96, від 50: 4.21) | V15: 4.69 | W15: як на сторінці | X15: 1 | Y15: 1 | Z15: точний MPN | AA15: 2026-10-25 | AB15: Космодром: Kingbright KP-1608SURCK (точний MPN), партнерський склад: під замовлення, 11.5 грн (без ПДВ), мін. 5 шт. 4-6 тижнів, ціна від 5 шт | AC15: відкрити | AD15: пошук | AF15: Дрібні пасивні | AG15: D502: ALERT (GPIO41) | AH15: KP-1608SURCK (Kingbright) | AI15: https://imrad.com.ua/ua/kp-1608surck-3 | AJ15: =IF(L15>0,IFERROR(MATCH(O15,Кошики!$A$2:$A$10,0),99)*1000+ROW(),"") -> 1015
A16: 11 | B16: F101 | C16: 2A 125V | D16: Fuse_Littelfuse-NANO2-451_453 | E16: Лише Littelfuse 0451002.MRL (NANO2 451, 2 А 125 В, дуже швидкий) під футпринт Fuse_Littelfuse-NANO2-451_453. 1206-запобіжники 0466 на цей футпринт не стають | F16: 1 | G16: шт | H16: =F16*Інструкція!$C$5 -> 5 | I16: =IF(H16=0,0,MAX(ROUNDUP(H16*INDEX(Інструкція!$C$9:$C$13,MATCH(AF16,Інструкція!$B$9:$B$13,0)),0),INDEX(Інструкція!$D$9:$D$13,MATCH(AF16,Інструкція!$B$9:$B$13,0)))) -> 1 | J16: 10 | K16: 0 | L16: =IF(N16<>"магазин",0,IF(MAX(0,MAX(H16+I16,J16)-K16)=0,0,MAX(X16,CEILING(MAX(0,MAX(H16+I16,J16)-K16),Y16)))) -> 10 | M16: =IF(N16="магазин",L16+K16-H16,IF(N16="книга резисторів 0603",(Набори!$D$5+Набори!$E$5)*Набори!$F$5-H16,"")) -> 5 | N16: магазин | O16: IMRAD | P16: Littelfuse 0451002.MRL (NANO2, 2 А 125 В, точний MPN) | Q16: в наявності | R16: =IF(V16="","",IF(W16="без ПДВ",V16*(1+Інструкція!$C$6),V16)) -> 49.95 | S16: =IF(L16=0,0,IF(R16="","",L16*R16)) -> 499.5 | T16: відкрити | U16: IMRAD: «Є в наявності, на складі» (кількість не показано); ціна від 8 шт (1 шт: 57.93, від 4: 55.03, від 24: 45.86) | V16: 49.95 | W16: як на сторінці | X16: 1 | Y16: 1 | Z16: точний MPN | AA16: 2026-10-25 | AB16: Космодром: Littelfuse 0451002.MRL (точний MPN; виробник на сайті «LTL»): в наявності, 8 грн (без ПДВ). на складі 806 шт; маркування перевірити при отриманні | AC16: відкрити | AD16: пошук | AF16: Мікросхеми та силові | AG16: F101: запобіжник входу батареї | AH16: 0451002.MRL (Littelfuse) | AI16: https://imrad.com.ua/ua/0451002-mrl-2 | AJ16: =IF(L16>0,IFERROR(MATCH(O16,Кошики!$A$2:$A$10,0),99)*1000+ROW(),"") -> 1016
A17: 12 | B17: F501 | C17: 0.25A 125V | D17: Fuse_1206_3216Metric | E17: Лише Littelfuse 0466.250NRHF (0.25 А, 125 В, дуже швидкий, 1206). Інший номінал не ставити: розраховано разом з R511 | F17: 1 | G17: шт | H17: =F17*Інструкція!$C$5 -> 5 | I17: =IF(H17=0,0,MAX(ROUNDUP(H17*INDEX(Інструкція!$C$9:$C$13,MATCH(AF17,Інструкція!$B$9:$B$13,0)),0),INDEX(Інструкція!$D$9:$D$13,MATCH(AF17,Інструкція!$B$9:$B$13,0)))) -> 1 | J17: 10 | K17: 0 | L17: =IF(N17<>"магазин",0,IF(MAX(0,MAX(H17+I17,J17)-K17)=0,0,MAX(X17,CEILING(MAX(0,MAX(H17+I17,J17)-K17),Y17)))) -> 10 | M17: =IF(N17="магазин",L17+K17-H17,IF(N17="книга резисторів 0603",(Набори!$D$5+Набори!$E$5)*Набори!$F$5-H17,"")) -> 5 | N17: магазин | O17: VD MAIS | P17: Littelfuse 0466.250NRHF (точний MPN), Digi-Key через VD MAIS | Q17: під замовлення | R17: =IF(V17="","",IF(W17="без ПДВ",V17*(1+Інструкція!$C$6),V17)) -> 71.436 | S17: =IF(L17=0,0,IF(R17="","",L17*R17)) -> 714.36 | T17: відкрити | U17: Digi-Key F5692CT-ND: 5812 шт, 3 тижні; ціна від 5 шт 59.53 грн без ПДВ (1 шт: 59.66), дані API VD MAIS; в IMRAD немає (0466.250NR - немає, 0451.250MRL - під замовлення). Замовляти разом з U101 | V17: 59.53 | W17: без ПДВ | X17: 5 | Y17: 1 | Z17: точний MPN | AA17: 2026-10-25 | AB17: Космодром: Littelfuse 0466.250NRHF (точний MPN), партнерський склад: під замовлення, 8.85 грн (без ПДВ), мін. 5 шт. 4-6 тижнів, ціна від 5 шт | AC17: відкрити | AD17: пошук | AF17: Мікросхеми та силові | AG17: F501: запобіжник виходу на вольтметр J503 | AH17: 0466.250NRHF (Littelfuse) | AI17: https://catalog.vdmais.ua/uk/parasearch/?keyword=0466.250NRHF | AJ17: =IF(L17>0,IFERROR(MATCH(O17,Кошики!$A$2:$A$10,0),99)*1000+ROW(),"") -> 2017
A18: 13 | B18: J101 | C18: BAT | D18: SolderWire-0.75sqmm_1x02_P4.8mm_D1.25mm_OD2.3mm | E18: Деталі немає: два отвори під провід 0.75 мм² (косичка XT30 від роз'єму на корпусі) | F18: 1 | G18: шт | H18: =F18*Інструкція!$C$5 -> 5 | I18: =IF(H18=0,0,MAX(ROUNDUP(H18*INDEX(Інструкція!$C$9:$C$13,MATCH(AF18,Інструкція!$B$9:$B$13,0)),0),INDEX(Інструкція!$D$9:$D$13,MATCH(AF18,Інструкція!$B$9:$B$13,0)))) -> 0 | J18: 0 | K18: 0 | L18: =IF(N18<>"магазин",0,IF(MAX(0,MAX(H18+I18,J18)-K18)=0,0,MAX(X18,CEILING(MAX(0,MAX(H18+I18,J18)-K18),Y18)))) -> 0 | M18: =IF(N18="магазин",L18+K18-H18,IF(N18="книга резисторів 0603",(Набори!$D$5+Набори!$E$5)*Набори!$F$5-H18,"")) | N18: не купується | O18: не купується | P18: провід XT30 0.5-0.75 мм² (поза платою) | Q18: не купується | R18: =IF(V18="","",IF(W18="без ПДВ",V18*(1+Інструкція!$C$6),V18)) | S18: =IF(L18=0,0,IF(R18="","",L18*R18)) -> 0 | W18: як на сторінці | X18: 1 | Y18: 1 | AF18: Без деталі | AG18: J101: провід батареї (BAT+ = квадратна площадка) | AH18: - | AJ18: =IF(L18>0,IFERROR(MATCH(O18,Кошики!$A$2:$A$10,0),99)*1000+ROW(),"")
A19: 14 | B19: J201 | C19: USB4105-GF-A | D19: USB_C_Receptacle_HRO_TYPE-C-31-M-12 | E19: GCT USB4105-GF-A на футпринті HRO TYPE-C-31-M-12 (сигнальні площадки ті самі; ніжки корпусу 0.80/1.10 мм у пазах 1.2/1.7 мм): приміряти на голій платі перед пайкою | F19: 1 | G19: шт | H19: =F19*Інструкція!$C$5 -> 5 | I19: =IF(H19=0,0,MAX(ROUNDUP(H19*INDEX(Інструкція!$C$9:$C$13,MATCH(AF19,Інструкція!$B$9:$B$13,0)),0),INDEX(Інструкція!$D$9:$D$13,MATCH(AF19,Інструкція!$B$9:$B$13,0)))) -> 1 | J19: 10 | K19: 0 | L19: =IF(N19<>"магазин",0,IF(MAX(0,MAX(H19+I19,J19)-K19)=0,0,MAX(X19,CEILING(MAX(0,MAX(H19+I19,J19)-K19),Y19)))) -> 10 | M19: =IF(N19="магазин",L19+K19-H19,IF(N19="книга резисторів 0603",(Набори!$D$5+Набори!$E$5)*Набори!$F$5-H19,"")) -> 5 | N19: магазин | O19: IMRAD | P19: GCT USB4105-GF-A (точний MPN) | Q19: в наявності | R19: =IF(V19="","",IF(W19="без ПДВ",V19*(1+Інструкція!$C$6),V19)) -> 34.96 | S19: =IF(L19=0,0,IF(R19="","",L19*R19)) -> 349.6 | T19: відкрити | U19: IMRAD: «Є в наявності, на складі» (кількість не показано); ціна від 8 шт (1 шт: 37.65, від 4: 36.30, від 20: 33.62) | V19: 34.96 | W19: як на сторінці | X19: 1 | Y19: 1 | Z19: точний MPN | AA19: 2026-10-25 | AB19: Космодром: GCT USB4105-GF-A (точний MPN): в наявності, 44 грн (без ПДВ). на складі 726 шт | AC19: відкрити | AD19: пошук | AF19: Роз'єми та кнопки | AG19: J201 USB-C: лише дані/прошивка, плату не живить | AH19: USB4105-GF-A (GCT) | AI19: https://imrad.com.ua/ua/usb4105-gf-a-1 | AJ19: =IF(L19>0,IFERROR(MATCH(O19,Кошики!$A$2:$A$10,0),99)*1000+ROW(),"") -> 1019
